2025-03-05 09:49:56,212 INFO    StreamThr :39048 [internal.py:wandb_internal():85] W&B internal server running at pid: 39048, started at: 2025-03-05 09:49:56.211646
2025-03-05 09:49:56,213 DEBUG   HandlerThread:39048 [handler.py:handle_request():158] handle_request: status
2025-03-05 09:49:56,221 INFO    WriterThread:39048 [datastore.py:open_for_write():87] open: /Users/jinseopsong/coding/StockTrading_based_on_financialnews/src/wandb/run-20250305_094956-7ea0fby9/run-7ea0fby9.wandb
2025-03-05 09:49:56,221 DEBUG   SenderThread:39048 [sender.py:send():391] send: header
2025-03-05 09:49:56,256 DEBUG   SenderThread:39048 [sender.py:send():391] send: run
2025-03-05 09:49:56,368 ERROR   SenderThread:39048 [internal_api.py:execute():349] 404 response executing GraphQL.
2025-03-05 09:49:56,369 ERROR   SenderThread:39048 [internal_api.py:execute():350] {"errors":[{"message":"entity your-wandb-username not found during upsertBucket","path":["upsertBucket"]}],"data":{"upsertBucket":null}}
2025-03-05 09:49:56,369 ERROR   SenderThread:39048 [sender.py:send_run():1021] It appears that you do not have permission to access the requested resource. Please reach out to the project owner to grant you access. If you have the correct permissions, verify that there are no issues with your networking setup.(Error 404: Not Found)
Traceback (most recent call last):
  File "/Users/jinseopsong/Library/Python/3.9/lib/python/site-packages/wandb/sdk/lib/retry.py", line 131, in __call__
    result = self._call_fn(*args, **kwargs)
  File "/Users/jinseopsong/Library/Python/3.9/lib/python/site-packages/wandb/sdk/internal/internal_api.py", line 345, in execute
    return self.client.execute(*args, **kwargs)  # type: ignore
  File "/Users/jinseopsong/Library/Python/3.9/lib/python/site-packages/wandb/vendor/gql-0.2.0/wandb_gql/client.py", line 52, in execute
    result = self._get_result(document, *args, **kwargs)
  File "/Users/jinseopsong/Library/Python/3.9/lib/python/site-packages/wandb/vendor/gql-0.2.0/wandb_gql/client.py", line 60, in _get_result
    return self.transport.execute(document, *args, **kwargs)
  File "/Users/jinseopsong/Library/Python/3.9/lib/python/site-packages/wandb/sdk/lib/gql_request.py", line 59, in execute
    request.raise_for_status()
  File "/Users/jinseopsong/Library/Python/3.9/lib/python/site-packages/requests/models.py", line 1024, in raise_for_status
    raise HTTPError(http_error_msg, response=self)
requests.exceptions.HTTPError: 404 Client Error: Not Found for url: https://api.wandb.ai/graphql

During handling of the above exception, another exception occurred:

Traceback (most recent call last):
  File "/Users/jinseopsong/Library/Python/3.9/lib/python/site-packages/wandb/sdk/internal/sender.py", line 1019, in send_run
    server_run = self._init_run(run, config_value_dict)
  File "/Users/jinseopsong/Library/Python/3.9/lib/python/site-packages/wandb/sdk/internal/sender.py", line 1091, in _init_run
    server_run, inserted, server_messages = self._api.upsert_run(
  File "/Users/jinseopsong/Library/Python/3.9/lib/python/site-packages/wandb/apis/normalize.py", line 73, in wrapper
    raise err
  File "/Users/jinseopsong/Library/Python/3.9/lib/python/site-packages/wandb/apis/normalize.py", line 41, in wrapper
    return func(*args, **kwargs)
  File "/Users/jinseopsong/Library/Python/3.9/lib/python/site-packages/wandb/sdk/internal/internal_api.py", line 2224, in upsert_run
    response = self.gql(
  File "/Users/jinseopsong/Library/Python/3.9/lib/python/site-packages/wandb/sdk/internal/internal_api.py", line 317, in gql
    ret = self._retry_gql(
  File "/Users/jinseopsong/Library/Python/3.9/lib/python/site-packages/wandb/sdk/lib/retry.py", line 147, in __call__
    retry_timedelta_triggered = check_retry_fn(e)
  File "/Users/jinseopsong/Library/Python/3.9/lib/python/site-packages/wandb/util.py", line 968, in check_retry_fn
    return fallback_retry_fn(e)
  File "/Users/jinseopsong/Library/Python/3.9/lib/python/site-packages/wandb/util.py", line 910, in no_retry_auth
    raise CommError(
wandb.errors.CommError: It appears that you do not have permission to access the requested resource. Please reach out to the project owner to grant you access. If you have the correct permissions, verify that there are no issues with your networking setup.(Error 404: Not Found)
2025-03-05 09:50:01,402 DEBUG   HandlerThread:39048 [handler.py:handle_request():158] handle_request: status_report
2025-03-05 09:50:06,419 DEBUG   HandlerThread:39048 [handler.py:handle_request():158] handle_request: status_report
2025-03-05 09:50:11,441 DEBUG   HandlerThread:39048 [handler.py:handle_request():158] handle_request: status_report
2025-03-05 09:50:16,463 DEBUG   HandlerThread:39048 [handler.py:handle_request():158] handle_request: status_report
2025-03-05 09:50:21,483 DEBUG   HandlerThread:39048 [handler.py:handle_request():158] handle_request: status_report
